<?xml version="1.0" ?>
<sdf version='1.4'>
  <model name='summit_xl'>
    <link name='base_footprint'>
      <pose>0 0 0 0 -0 0</pose>
      <inertial>
        <pose>0.000547096 0 0.11651 0 -0 0</pose>
        <mass>25.102</mass>
        <inertia>
          <ixx>1.49293</ixx>
          <ixy>0.004</ixy>
          <ixz>0.00188695</ixz>
          <iyy>6.9568</iyy>
          <iyz>0</iyz>
          <izz>6.22727</izz>
        </inertia>
      </inertial>
      <collision name='base_footprint_collision_base_link'>
        <pose>0 0 0.117 0 -0 0</pose>
        <geometry>
          <mesh>
            <scale>1 1 1</scale>
            <uri>/home/daniel/catkin/src/summit_xl_common/summit_xl_description/meshes/bases/summit_xl_chassis_collision.dae</uri>
          </mesh>1
        </geometry>
        <surface>
          <contact>
            <ode/>
          </contact>
          <friction>
            <ode/>
          </friction>
          <bounce/>
        </surface>
        <max_contacts>10</max_contacts>
      </collision>
      <collision name='base_footprint_collision_camera_link'>
        <pose>0.141332 0 -0.0105423 0 0.261799 0</pose>
        <geometry>
          <mesh>
            <scale>1 1 1</scale>
            <uri>/home/daniel/catkin/src/robotnik_sensors/meshes/axis_p5512.stl</uri>
          </mesh>
        </geometry>
        <surface>
          <contact>
            <ode/>
          </contact>
          <friction>
            <ode/>
          </friction>
          <bounce/>
        </surface>
        <surface>
          <contact>
            <ode/>
          </contact>
          <friction>
            <ode/>
          </friction>
        </surface>
        <max_contacts>10</max_contacts>
      </collision>
      <collision name='base_footprint_collision_gps_link'>
        <pose>-0.22 0 0.392 0 -0 0</pose>
        <geometry>
          <mesh>
            <scale>1 1 1</scale>
            <uri>/home/daniel/catkin/src/robotnik_sensors/meshes/antenna_3GO16.stl</uri>
          </mesh>
        </geometry>
        <surface>
          <contact>
            <ode/>
          </contact>
          <friction>
            <ode/>
          </friction>
          <bounce/>
        </surface>
        <surface>
          <contact>
            <ode/>
          </contact>
          <friction>
            <ode/>
          </friction>
        </surface>
        <max_contacts>10</max_contacts>
      </collision>
      <collision name='base_footprint_collision_imu_link'>
        <pose>-0.18 0 0.287 0 -0 0</pose>
        <geometry>
          <box>
            <size>0.001 0.001 0.001</size>
          </box>
        </geometry>
        <surface>
          <contact>
            <ode/>
          </contact>
          <friction>
            <ode/>
          </friction>
          <bounce/>
        </surface>
        <max_contacts>10</max_contacts>
      </collision>
      <visual name='base_footprint_visual'>
        <pose>0 0 0 0 -0 0</pose>
        <geometry>
          <box>
            <size>0.001 0.001 0.001</size>
          </box>
        </geometry>
        <material>
          <script>
            <name>Gazebo/Green</name>
            <uri>__default__</uri>
          </script>
        </material>
      </visual>
      <visual name='base_footprint_visual_base_link'>
        <pose>0 0 0.117 0 -0 0</pose>
        <geometry>
          <mesh>
            <scale>1 1 1</scale>
            <uri>/home/daniel/catkin/src/summit_xl_common/summit_xl_description/meshes/bases/summit_xl_chassis.dae</uri>
          </mesh>
        </geometry>
      </visual>
      <visual name='base_footprint_visual_camera_link'>
        <pose>0.141332 0 -0.0105423 0 0.261799 0</pose>
        <geometry>
          <mesh>
            <scale>1 1 1</scale>
            <uri>/home/daniel/catkin/src/robotnik_sensors/meshes/axis_p5512.stl</uri>
          </mesh>
        </geometry>
        <material>
          <script>
            <name>Gazebo/FlatBlack</name>
            <uri>__default__</uri>
          </script>
        </material>
      </visual>
      <visual name='base_footprint_visual_gps_link'>
        <pose>-0.22 0 0.392 0 -0 0</pose>
        <geometry>
          <mesh>
            <scale>1 1 1</scale>
            <uri>/home/daniel/catkin/src/robotnik_sensors/meshes/antenna_3GO16.stl</uri>
          </mesh>
        </geometry>
        <material>
          <script>
            <name>Gazebo/White</name>
            <uri>__default__</uri>
          </script>
        </material>
      </visual>
      <visual name='base_footprint_visual_hokuyo_base_laser_link'>
        <pose>0 0 0.447 0 -0 0</pose>
        <geometry>
          <mesh>
            <scale>1 1 1</scale>
            <uri>/home/daniel/catkin/src/robotnik_sensors/meshes/hokuyo_utm_30lx.dae</uri>
          </mesh>
        </geometry>
      </visual>
      <visual name='base_footprint_visual_imu_link'>
        <pose>-0.18 0 0.287 0 -0 0</pose>
        <geometry>
          <box>
            <size>0.001 0.001 0.001</size>
          </box>
        </geometry>
      </visual>
      <velocity_decay>
        <linear>0</linear>
        <angular>0</angular>
      </velocity_decay>
      <velocity_decay>
        <linear>0</linear>
        <angular>0</angular>
      </velocity_decay>
      <velocity_decay>
        <linear>0</linear>
        <angular>0</angular>
      </velocity_decay>
      <gravity>1</gravity>
      <gravity>1</gravity>
      <velocity_decay>
        <linear>0</linear>
        <angular>0</angular>
      </velocity_decay>
      <self_collide>0</self_collide>
      <sensor name='hokuyo_base_sensor' type='ray'>
        <visualize>0</visualize>
        <update_rate>30</update_rate>
        <ray>
          <scan>
            <horizontal>
              <samples>1081</samples>
              <resolution>1</resolution>
              <min_angle>2.35</min_angle>
              <max_angle>-2.35</max_angle>
            </horizontal>
          </scan>
          <range>
            <min>0.1</min>
            <max>30</max>
            <resolution>0.01</resolution>
          </range>
          <noise>
            <type>gaussian</type>
            <mean>0</mean>
            <stddev>0.01</stddev>
          </noise>
        </ray>
        <!--plugin name='gazebo_ros_head_hokuyo_controller' filename='libgazebo_ros_laser.so'>
          <topicName>hokuyo_base/scan</topicName>
          <frameName>hokuyo_base_laser_link</frameName>
          <robotNamespace>/</robotNamespace>
        </plugin-->
        <pose>0 0 0.447 0 -0 0</pose>
      </sensor>
      <kinematic>0</kinematic>
    </link>
    <link name='camera_pan_link'>
      <pose>0.215882 0 0.383593 0 0.261799 0</pose>
      <inertial>
        <pose>0 0 0 0 -0 0</pose>
        <mass>0.1</mass>
        <inertia>
          <ixx>0.1</ixx>
          <ixy>0</ixy>
          <ixz>0</ixz>
          <iyy>0.1</iyy>
          <iyz>0</iyz>
          <izz>0.1</izz>
        </inertia>
      </inertial>
      <velocity_decay>
        <linear>0</linear>
        <angular>0</angular>
      </velocity_decay>
      <self_collide>0</self_collide>
      <kinematic>0</kinematic>
      <gravity>1</gravity>
    </link>
    <joint name='joint_camera_pan' type='revolute'>
      <child>camera_pan_link</child>
      <parent>base_footprint</parent>
      <axis>
        <xyz>0.258819 0 0.965926</xyz>
        <limit>
          <lower>-1e+16</lower>
          <upper>1e+16</upper>
        </limit>
        <dynamics/>
      </axis>
    </joint>
    <link name='camera_tilt_link'>
      <pose>0.215882 0 0.383593 0 0.261799 0</pose>
      <inertial>
        <pose>0 0 0 0 -0 0</pose>
        <mass>0.1</mass>
        <inertia>
          <ixx>0.1</ixx>
          <ixy>0</ixy>
          <ixz>0</ixz>
          <iyy>0.1</iyy>
          <iyz>0</iyz>
          <izz>0.1</izz>
        </inertia>
      </inertial>
      <gravity>1</gravity>
      <velocity_decay>
        <linear>0</linear>
        <angular>0</angular>
      </velocity_decay>
      <self_collide>0</self_collide>
      <sensor name='camera1' type='camera'>
        <update_rate>30</update_rate>
        <camera name='head'>
          <horizontal_fov>1.39626</horizontal_fov>
          <image>
            <width>800</width>
            <height>800</height>
            <format>R8G8B8</format>
          </image>
          <clip>
            <near>0.03</near>
            <far>300</far>
          </clip>
          <noise>
            <type>gaussian</type>
            <mean>0</mean>
            <stddev>0.007</stddev>
          </noise>
        </camera>
        <!--plugin name='camera_controller' filename='libgazebo_ros_camera.so'>
          <alwaysOn>true</alwaysOn>
          <updateRate>0.0</updateRate>
          <cameraName>camera</cameraName>
          <imageTopicName>image_raw</imageTopicName>
          <cameraInfoTopicName>camera_info</cameraInfoTopicName>
          <frameName>camera_tilt_link</frameName>
          <hackBaseline>0.07</hackBaseline>
          <distortionK1>0.0</distortionK1>
          <distortionK2>0.0</distortionK2>
          <distortionK3>0.0</distortionK3>
          <distortionT1>0.0</distortionT1>
          <distortionT2>0.0</distortionT2>
          <robotNamespace>/</robotNamespace>
        </plugin-->
      </sensor>
      <kinematic>0</kinematic>
    </link>
    <joint name='joint_camera_tilt' type='revolute'>
      
      <child>camera_tilt_link</child>
      <parent>camera_pan_link</parent>
      <axis>
        <xyz>0 1 0</xyz>
        <limit>
          <lower>-1e+16</lower>
          <upper>1e+16</upper>
        </limit>
        <dynamics/>
      </axis>
    </joint>
    <link name='back_left_wheel'>
      <pose>-0.229 0.234 0.117 0 -0 0</pose>
      <inertial>
        <pose>0 0 0 0 -0 0</pose>
        <mass>6.5</mass>
        <inertia>
          <ixx>0.0328613</ixx>
          <ixy>0</ixy>
          <ixz>0</ixz>
          <iyy>0.0328613</iyy>
          <iyz>0</iyz>
          <izz>0.0444893</izz>
        </inertia>
      </inertial>
      <collision name='back_left_wheel_collision'>
        <pose>0 0 0 1.5708 -0 0</pose>
        <geometry>
          <cylinder>
            <length>0.14</length>
            <radius>0.117</radius>
          </cylinder>
        </geometry>
        <surface>
          <contact>
            <ode>
              <kp>1e+07</kp>
              <kd>1</kd>
            </ode>
          </contact>
          <friction>
            <ode>
              <mu>1</mu>
              <mu2>1</mu2>
              <fdir1>1 0 0</fdir1>
            </ode>
          </friction>
          <bounce/>
        </surface>
        <max_contacts>10</max_contacts>
      </collision>
      <visual name='back_left_wheel_visual'>
        <pose>0 0 0 0 -0 0</pose>
        <geometry>
          <mesh>
            <scale>1 1 1</scale>
            <uri>/home/daniel/catkin/src/summit_xl_common/summit_xl_description/meshes/wheels/rubber_wheel_left.dae</uri>
          </mesh>
        </geometry>
      </visual>
      <gravity>1</gravity>
      <velocity_decay>
        <linear>0</linear>
        <angular>0</angular>
      </velocity_decay>
      <self_collide>0</self_collide>
      <kinematic>0</kinematic>
    </link>
    <joint name='joint_back_left_wheel' type='revolute'>
      <child>back_left_wheel</child>
      <parent>base_footprint</parent>
      <axis>
        <xyz>0 1 0</xyz>
        <limit>
          <lower>-1e+16</lower>
          <upper>1e+16</upper>
        </limit>
        <dynamics/>
      </axis>
    </joint>
    <link name='back_right_wheel'>
      <pose>-0.229 -0.234 0.117 0 -0 0</pose>
      <inertial>
        <pose>0 0 0 0 -0 0</pose>
        <mass>6.5</mass>
        <inertia>
          <ixx>0.0328613</ixx>
          <ixy>0</ixy>
          <ixz>0</ixz>
          <iyy>0.0328613</iyy>
          <iyz>0</iyz>
          <izz>0.0444893</izz>
        </inertia>
      </inertial>
      <collision name='back_right_wheel_collision'>
        <pose>0 0 0 1.5708 -0 0</pose>
        <geometry>
          <cylinder>
            <length>0.14</length>
            <radius>0.117</radius>
          </cylinder>
        </geometry>
        <surface>
          <contact>
            <ode>
              <kp>1e+07</kp>
              <kd>1</kd>
            </ode>
          </contact>
          <friction>
            <ode>
              <mu>1</mu>
              <mu2>1</mu2>
              <fdir1>1 0 0</fdir1>
            </ode>
          </friction>
          <bounce/>
        </surface>
        <max_contacts>10</max_contacts>
      </collision>
      <visual name='back_right_wheel_visual'>
        <pose>0 0 0 0 -0 0</pose>
        <geometry>
          <mesh>
            <scale>1 1 1</scale>
            <uri>/home/daniel/catkin/src/summit_xl_common/summit_xl_description/meshes/wheels/rubber_wheel_right.dae</uri>
          </mesh>
        </geometry>
      </visual>
      <gravity>1</gravity>
      <velocity_decay>
        <linear>0</linear>
        <angular>0</angular>
      </velocity_decay>
      <self_collide>0</self_collide>
      <kinematic>0</kinematic>
    </link>
    <joint name='joint_back_right_wheel' type='revolute'>
      <child>back_right_wheel</child>
      <parent>base_footprint</parent>
      <axis>
        <xyz>0 1 0</xyz>
        <limit>
          <lower>-1e+16</lower>
          <upper>1e+16</upper>
        </limit>
        <dynamics/>
      </axis>
    </joint>
    <link name='front_left_wheel'>
      <pose>0.229 0.234 0.117 0 -0 0</pose>
      <inertial>
        <pose>0 0 0 0 -0 0</pose>
        <mass>6.5</mass>
        <inertia>
          <ixx>0.0328613</ixx>
          <ixy>0</ixy>
          <ixz>0</ixz>
          <iyy>0.0328613</iyy>
          <iyz>0</iyz>
          <izz>0.0444893</izz>
        </inertia>
      </inertial>
      <collision name='front_left_wheel_collision'>
        <pose>0 0 0 1.5708 -0 0</pose>
        <geometry>
          <cylinder>
            <length>0.14</length>
            <radius>0.117</radius>
          </cylinder>
        </geometry>
        <surface>
          <contact>
            <ode>
              <kp>1e+07</kp>
              <kd>1</kd>
            </ode>
          </contact>
          <friction>
            <ode>
              <mu>1</mu>
              <mu2>1</mu2>
              <fdir1>1 0 0</fdir1>
            </ode>
          </friction>
          <bounce/>
        </surface>
        <max_contacts>10</max_contacts>
      </collision>
      <visual name='front_left_wheel_visual'>
        <pose>0 0 0 0 -0 0</pose>
        <geometry>
          <mesh>
            <scale>1 1 1</scale>
            <uri>/home/daniel/catkin/src/summit_xl_common/summit_xl_description/meshes/wheels/rubber_wheel_left.dae</uri>
          </mesh>
        </geometry>
      </visual>
      <gravity>1</gravity>
      <velocity_decay>
        <linear>0</linear>
        <angular>0</angular>
      </velocity_decay>
      <self_collide>0</self_collide>
      <kinematic>0</kinematic>
    </link>
    <joint name='joint_front_left_wheel' type='revolute'>
      <child>front_left_wheel</child>
      <parent>base_footprint</parent>
      <axis>
        <xyz>0 1 0</xyz>
        <limit>
          <lower>-1e+16</lower>
          <upper>1e+16</upper>
        </limit>
        <dynamics/>
      </axis>
    </joint>
    <link name='front_right_wheel'>
      <pose>0.229 -0.234 0.117 0 -0 0</pose>
      <inertial>
        <pose>0 0 0 0 -0 0</pose>
        <mass>6.5</mass>
        <inertia>
          <ixx>0.0328613</ixx>
          <ixy>0</ixy>
          <ixz>0</ixz>
          <iyy>0.0328613</iyy>
          <iyz>0</iyz>
          <izz>0.0444893</izz>
        </inertia>
      </inertial>
      <collision name='front_right_wheel_collision'>
        <pose>0 0 0 1.5708 -0 0</pose>
        <geometry>
          <cylinder>
            <length>0.14</length>
            <radius>0.117</radius>
          </cylinder>
        </geometry>
        <surface>
          <contact>
            <ode>
              <kp>1e+07</kp>
              <kd>1</kd>
            </ode>
          </contact>
          <friction>
            <ode>
              <mu>1</mu>
              <mu2>1</mu2>
              <fdir1>1 0 0</fdir1>
            </ode>
          </friction>
          <bounce/>
        </surface>
        <max_contacts>10</max_contacts>
      </collision>
      <visual name='front_right_wheel_visual'>
        <pose>0 0 0 0 -0 0</pose>
        <geometry>
          <mesh>
            <scale>1 1 1</scale>
            <uri>/home/daniel/catkin/src/summit_xl_common/summit_xl_description/meshes/wheels/rubber_wheel_right.dae</uri>
          </mesh>
        </geometry>
      </visual>
      <gravity>1</gravity>
      <velocity_decay>
        <linear>0</linear>
        <angular>0</angular>
      </velocity_decay>
      <self_collide>0</self_collide>
      <kinematic>0</kinematic>
    </link>
    <joint name='joint_front_right_wheel' type='revolute'>
      <child>front_right_wheel</child>
      <parent>base_footprint</parent>
      <axis>
        <xyz>0 1 0</xyz>
        <limit>
          <lower>-1e+16</lower>
          <upper>1e+16</upper>
        </limit>
        <dynamics/>
      </axis>
    </joint>
    <!--plugin name='ros_control' filename='libgazebo_ros_control.so'>
      <robotNamespace>/summit_xl</robotNamespace>
      <robotParam>robot_description</robotParam>
      <controlPeriod>0.001</controlPeriod>
      <robotSimType>gazebo_ros_control/DefaultRobotHWSim</robotSimType>
    </plugin-->
    <!--plugin name='skid_steer_drive_controller' filename='libgazebo_ros_skid_steer_drive.so'>
      <robotNamespace>/summit_xl</robotNamespace>
      <updateRate>100.0</updateRate>
      <leftFrontJoint>joint_front_left_wheel</leftFrontJoint>
      <rightFrontJoint>joint_front_right_wheel</rightFrontJoint>
      <leftRearJoint>joint_back_left_wheel</leftRearJoint>
      <rightRearJoint>joint_back_right_wheel</rightRearJoint>
      <wheelSeparation>1.5</wheelSeparation>
      <wheelDiameter>0.234</wheelDiameter>
      <robotBaseFrame>base_footprint</robotBaseFrame>
      <torque>50</torque>
      <commandTopic>/summit_xl_control/cmd_vel</commandTopic>
      <odometryTopic>odom</odometryTopic>
      <odometryFrame>/odom</odometryFrame>
      <broadcastTF>1</broadcastTF>
    </plugin-->
    <!--plugin name='ros_imu' filename='libgazebo_ros_imu.so'>
      <topicName>imu_data</topicName>
      <serviceName>imu_service</serviceName>
      <gaussianNoise>0.005</gaussianNoise>
      <robotNamespace>/</robotNamespace>
      <bodyName>base_footprint</bodyName>
      <xyzOffset>0.18 0 -0.287</xyzOffset>
      <rpyOffset>0 -0 0</rpyOffset>
    </plugin-->
    <static>0</static>
    <!--plugin name='gps_link' filename='libhector_gazebo_ros_gps.so'>
      <alwaysOn>1</alwaysOn>
      <updateRate>5.0</updateRate>
      <bodyName>base_footprint</bodyName>
      <topicName>mavros/gps/fix</topicName>
      <referenceLatitude>39.493800</referenceLatitude>
      <referenceLongitude>-0.377982</referenceLongitude>
      <velocityTopicName>fix_velocity</velocityTopicName>
      <drift>0.0001 0.0001 0.0001</drift>
      <gaussianNoise>0.1 0.1 0.1</gaussianNoise>
      <velocityDrift>0 0 0</velocityDrift>
      <velocityGaussianNoise>0.1 0.1 0.1</velocityGaussianNoise>
      <robotNamespace>/</robotNamespace>
    </plugin-->
    <pose>0 0 0 0 -0 0</pose>
  </model>   
</sdf>
